<robot name="onshape">
<link name="e1">
<visual>
<origin xyz="0 0 0" rpy="1.570796326794896558 -0 -1.570796326794896558" />
<geometry>
<mesh filename="file://$(find hath)/src/description/meshes/e1.stl"/>
</geometry>
<material name="e1_material">
<color rgba="0.79215686274509800047 0.81960784313725487671 0.93333333333333334814 1.0"/>
</material>
</visual>
<collision>
<origin xyz="0 0 0" rpy="1.570796326794896558 -0 -1.570796326794896558" />
<geometry>
<mesh filename="file://$(find hath)/src/description/meshes/e1.stl"/>
</geometry>
</collision>
<inertial>
<origin xyz="-3.7970753644472524701e-16 3.0708669268189419697e-16 0.084869144365845736178" rpy="0 0 0"/>
<mass value="95.326366640812040032" />
<inertia ixx="12.630874432683471653" ixy="1.7206677941847264689e-14"  ixz="7.3120036664136709117e-15" iyy="12.482312674068598568" iyz="-4.2484821022772146146e-15" izz="18.731998096528414521" />
</inertial>
</link>

<link name="e2">
<visual>
<origin xyz="0 0 0.025000000000000008327" rpy="-1.570796326794896558 -1.570796326794896558 0" />
<geometry>
<mesh filename="file://$(find hath)/src/description/meshes/e2.stl"/>
</geometry>
<material name="e2_material">
<color rgba="0.79215686274509800047 0.81960784313725487671 0.93333333333333334814 1.0"/>
</material>
</visual>
<collision>
<origin xyz="0 0 0.025000000000000008327" rpy="-1.570796326794896558 -1.570796326794896558 0" />
<geometry>
<mesh filename="file://$(find hath)/src/description/meshes/e2.stl"/>
</geometry>
</collision>
<inertial>
<origin xyz="0.4749999999999999778 4.3474480473069823218e-19 0.025000000000000011796" rpy="0 0 0"/>
<mass value="2.6162927999999996409" />
<inertia ixx="0.00053840131775999982861" ixy="6.1332061310000917834e-45"  ixz="-4.0253318085083912055e-48" iyy="0.24485606431776021918" iyz="4.6574280432349153179e-21" izz="0.24488962462368024653" />
</inertial>
</link>

<link name="e3">
<visual>
<origin xyz="0 0 -0.024999999999999966693" rpy="-1.570796326794896558 -1.570796326794896558 0" />
<geometry>
<mesh filename="file://$(find hath)/src/description/meshes/e3.stl"/>
</geometry>
<material name="e3_material">
<color rgba="0.79215686274509800047 0.81960784313725487671 0.93333333333333334814 1.0"/>
</material>
</visual>
<collision>
<origin xyz="0 0 -0.024999999999999966693" rpy="-1.570796326794896558 -1.570796326794896558 0" />
<geometry>
<mesh filename="file://$(find hath)/src/description/meshes/e3.stl"/>
</geometry>
</collision>
<inertial>
<origin xyz="-5.5926671212169533675e-19 0.024999999999999990979 -0.024999999999999959754" rpy="0 0 0"/>
<mass value="0.42929279999999997441" />
<inertia ixx="0.00049543947072000027541" ixy="5.8624924491365394486e-34"  ixz="-1.4870408963755388034e-33" iyy="0.00021035131776000017597" iyz="1.6134793718248339738e-34" izz="0.00049543947072000016699" />
</inertial>
</link>

<link name="e4">
<visual>
<origin xyz="0 0 -0.63000000000000000444" rpy="-2.3523686426266381469e-31 -1.5247808850011199512e-40 -1.5077037809858845948e-44" />
<geometry>
<mesh filename="file://$(find hath)/src/description/meshes/e4.stl"/>
</geometry>
<material name="e4_material">
<color rgba="0.79215686274509800047 0.81960784313725487671 0.93333333333333334814 1.0"/>
</material>
</visual>
<collision>
<origin xyz="0 0 -0.63000000000000000444" rpy="-2.3523686426266381469e-31 -1.5247808850011199512e-40 -1.5077037809858845948e-44" />
<geometry>
<mesh filename="file://$(find hath)/src/description/meshes/e4.stl"/>
</geometry>
</collision>
<inertial>
<origin xyz="-3.3477703339821975432e-19 1.9692766670468804608e-20 -0.38721352184658541784" rpy="0 0 0"/>
<mass value="1.8145851753705573017" />
<inertia ixx="0.075504483690560356135" ixy="-2.1841891328661587495e-45"  ixz="1.1457793727377727704e-41" iyy="0.075504483690560356135" iyz="-1.778328608651823408e-32" izz="0.00036061324933751268433" />
</inertial>
</link>

<joint name="z" type="prismatic">
<origin xyz="-0.39604517031157382423 0.050000000000000002776 -0.025000000000000133227" rpy="-1.57079632679489678 -1.1511376128497489384e-14 1.5707963267948858999" />
<parent link="e3" />
<child link="e4" />
<axis xyz="0 0 1"/>
<limit effort="100" velocity="200" lower="-0.100" upper="0.159"/>
<joint_properties friction="0.0"/>
</joint>

<joint name="y_axis" type="prismatic">
<origin xyz="0.86499999999999876987 0 0.025000000000000008327" rpy="-1.570796326794896558 -1.065814103631468549e-14 1.5707963267949136554" />
<parent link="e2" />
<child link="e3" />
<axis xyz="0 0 1"/>
<limit effort="100" velocity="200" lower="0.05999999999999999778" upper="0.83999999999999996891"/>
<joint_properties friction="0.0"/>
</joint>

<joint name="x" type="prismatic">
<origin xyz="0.400 0.4749999999999999778 0.60499999999999998224" rpy="1.570796326794896558 -0 -1.570796326794896558" />
<parent link="e1" />
<child link="e2" />
<axis xyz="0 0 1"/>
<limit effort="100" velocity="200" lower="0.0" upper="0.630"/>
<joint_properties friction="0.0"/>
</joint>
<gazebo>
        <plugin filename="ign_ros2_control-system" name="ign_ros2_control::IgnitionROS2ControlPlugin">
   
            <parameters>$(find hath)/config/hath_controller.yaml</parameters>
        </plugin>
    </gazebo>
<ros2_control name="hath_controller" type="system">

 <hardware>
   <!-- <plugin>kai/RobotSystem</plugin> -->
   <plugin>ign_ros2_control/IgnitionSystem</plugin>
   <param name="example_param_write_for_sec">2</param>
   <param name="example_param_read_for_sec">2</param>
 </hardware>
 <joint name="x">
   <command_interface name="position">
     <param name="min">0</param>
     <param name="max">3.141592653589793116</param>
   </command_interface>  
   <command_interface name="velocity">
    <param name="min">-200</param>
    <param name="max">200</param>
  </command_interface>
  <command_interface name="effort">
    <param name="min">-100</param>
    <param name="max">100</param>
  </command_interface>
   <state_interface name="position"/>
 </joint>
 <joint name="y_axis">
   <command_interface name="position">
     <param name="min">-2</param>
     <param name="max">1.141592653589793116</param>
   </command_interface>
     <command_interface name="velocity">
    <param name="min">-200</param>
    <param name="max">200</param>
  </command_interface>
  <command_interface name="effort">
    <param name="min">-100</param>
    <param name="max">100</param>
  </command_interface>
    <state_interface name="position"/>
    </joint>
 <joint name="z">
   <command_interface name="position">
     <param name="min">-1</param>
     <param name="max">2.141592653589793116</param>
   </command_interface>
     <command_interface name="velocity">
    <param name="min">-200</param>
    <param name="max">200</param>
  </command_interface>
  <command_interface name="effort">
    <param name="min">-100</param>
    <param name="max">100</param>
  </command_interface>
    <state_interface name="position"/>
 </joint>
</ros2_control>
</robot>
