<robot name="onshape">
<link name="mg995">
<visual>
<origin xyz="0.014246661106962986085 0.018148050393590749174 0.079500000000000098366" rpy="2.9673693176031182817e-16 2.0210363832494955364e-17 -1.0512745417145308302" />
<geometry>
<mesh filename="package:///mg995.stl"/>
</geometry>
<material name="mg995_material">
<color rgba="0.10980392156862744946 0.10980392156862744946 0.10980392156862744946 1.0"/>
</material>
</visual>
<collision>
<origin xyz="0.014246661106962986085 0.018148050393590749174 0.079500000000000098366" rpy="2.9673693176031182817e-16 2.0210363832494955364e-17 -1.0512745417145308302" />
<geometry>
<mesh filename="package:///mg995.stl"/>
</geometry>
</collision>
<inertial>
<origin xyz="-0.0022603466340449626833 0.0085140121381946896884 0.079500007367540773129" rpy="0 0 0"/>
<mass value="0.058000000000000002942" />
<inertia ixx="9.6824739598764522283e-06" ixy="4.289189438683360203e-07"  ixz="2.714631065959707068e-12" iyy="9.0363456563254120714e-06" iyz="6.5738451268317901709e-12" izz="1.4928256821169687632e-05" />
</inertial>
</link>

<link name="mg995_2">
<visual>
<origin xyz="-0.010000000000000000208 1.5407439555097886824e-33 -0.044499999999999990952" rpy="-1.570796326794896558 -4.8617306858290169587e-63 2.1849301382993296918e-62" />
<geometry>
<mesh filename="package:///mg995.stl"/>
</geometry>
<material name="mg995_material">
<color rgba="0.10980392156862744946 0.10980392156862744946 0.10980392156862744946 1.0"/>
</material>
</visual>
<collision>
<origin xyz="-0.010000000000000000208 1.5407439555097886824e-33 -0.044499999999999990952" rpy="-1.570796326794896558 -4.8617306858290169587e-63 2.1849301382993296918e-62" />
<geometry>
<mesh filename="package:///mg995.stl"/>
</geometry>
</collision>
<inertial>
<origin xyz="-0.0098322614521223448969 7.3675406714344509814e-09 -0.025388017856651561022" rpy="0 0 0"/>
<mass value="0.058000000000000002942" />
<inertia ixx="8.8259081181983891712e-06" ixy="-4.3587507591215502402e-12"  ixz="-6.0974203095532659703e-08" iyy="1.4928256821169738454e-05" iyz="-5.6201381977063910251e-12" izz="9.8929114980025840498e-06" />
</inertial>
</link>

<link name="base">
<inertial>
<origin xyz="0 0 0" rpy="0 0 0" />
<mass value="1e-9" />
<inertia ixx="0" ixy="0" ixz="0" iyy="0" iyz="0" izz="0" />
</inertial>
</link>
<joint name="base_frame" type="fixed">
<origin xyz="-0.010000000000000000208 0.0022040872588557753296 -0.069499999999999992339" rpy="5.3926038442842590201e-33 -5.3926038442842289141e-33 -1.570796326794896558" />
<parent link="mg995_2" />
<child link="base" />
<axis xyz="0 0 0"/>
</joint>

<joint name="baseyaw" type="revolute">
<origin xyz="-1.3877787807814456755e-17 0.010000000000000005412 0.06950000000000011724" rpy="1.2325951644078287564e-32 -2.3111159332646792604e-33 1.570796326794896558" />
<parent link="mg995" />
<child link="mg995_2" />
<axis xyz="0 0 1"/>
<limit effort="1" velocity="20" lower="0" upper="3.141592653589793116"/>
<joint_properties friction="0.0"/>
</joint>

<link name="assembly_1">
<visual>
<origin xyz="-4.4755865680201623036e-15 0.089034298211336168616 -2.0816681711721685133e-17" rpy="-1.5707963267948970021 -1.2806630172647252295e-15 1.5707963267948992225" />
<geometry>
<mesh filename="package:///mg995.stl"/>
</geometry>
<material name="mg995_material">
<color rgba="0.10980392156862744946 0.10980392156862744946 0.10980392156862744946 1.0"/>
</material>
</visual>
<collision>
<origin xyz="-4.4755865680201623036e-15 0.089034298211336168616 -2.0816681711721685133e-17" rpy="-1.5707963267948970021 -1.2806630172647252295e-15 1.5707963267948992225" />
<geometry>
<mesh filename="package:///mg995.stl"/>
</geometry>
</collision>
<visual>
<origin xyz="-2.6229018956769323268e-15 0.049855142831802229386 -3.4694469519536141888e-18" rpy="1.570796326794896558 -1.1903935229434375023e-17 1.2883445191167409088e-18" />
<geometry>
<mesh filename="package:///outarm.stl"/>
</geometry>
<material name="outarm_material">
<color rgba="0.61568627450980395466 0.81176470588235294379 0.92941176470588238168 1.0"/>
</material>
</visual>
<collision>
<origin xyz="-2.6229018956769323268e-15 0.049855142831802229386 -3.4694469519536141888e-18" rpy="1.570796326794896558 -1.1903935229434375023e-17 1.2883445191167409088e-18" />
<geometry>
<mesh filename="package:///outarm.stl"/>
</geometry>
</collision>
<inertial>
<origin xyz="-6.0383965149810555361e-09 0.082046802534002719054 0.015213052205729072144" rpy="0 0 0"/>
<mass value="0.070766740240779890669" />
<inertia ixx="5.0581928568000257952e-05" ixy="7.4163072495688462003e-12"  ixz="7.2862191653951591525e-12" iyy="1.4192326667764486103e-05" iyz="-9.0300242728862691033e-06" izz="4.1085228957357451294e-05" />
</inertial>
</link>

<link name="outarm">
<visual>
<origin xyz="0.049179155379533628922 1.8457457784393227485e-15 3.4694469519536141888e-18" rpy="1.570796326794896558 -5.0490281934899054697e-18 1.570796326794896558" />
<geometry>
<mesh filename="package:///outarm.stl"/>
</geometry>
<material name="outarm_material">
<color rgba="0.61568627450980395466 0.81176470588235294379 0.92941176470588238168 1.0"/>
</material>
</visual>
<collision>
<origin xyz="0.049179155379533628922 1.8457457784393227485e-15 3.4694469519536141888e-18" rpy="1.570796326794896558 -5.0490281934899054697e-18 1.570796326794896558" />
<geometry>
<mesh filename="package:///outarm.stl"/>
</geometry>
</collision>
<inertial>
<origin xyz="0.049494116571571072916 1.9966477129750254427e-15 -0.0024999999999999965826" rpy="0 0 0"/>
<mass value="0.012766740240779891197" />
<inertia ixx="4.7912950654648192505e-07" ixy="1.6195445818671237441e-21"  ixz="-1.5771206474075743739e-22" iyy="1.4306570639020512877e-05" iyz="5.2019280474227799155e-25" izz="1.473250539456373924e-05" />
</inertial>
</link>

<joint name="outarm" type="revolute">
<origin xyz="-3.9621084191310274036e-15 0.099034298211335899942 0.044499999999999789724" rpy="-3.1415926535897900074 -2.1456705084130752623e-15 0.77445109514413923435" />
<parent link="assembly_1" />
<child link="outarm" />
<axis xyz="0 0 1"/>
<limit effort="1" velocity="20" lower="0" upper="3.141592653589793116"/>
<joint_properties friction="0.0"/>
</joint>

<joint name="motor2" type="revolute">
<origin xyz="-0.01941721109241918708 -0.012625212490669088933 0.079500000000000237144" rpy="1.5707963267948970021 -0.45450288711037684086 2.0903181118752649503" />
<parent link="mg995" />
<child link="assembly_1" />
<axis xyz="0 0 1"/>
<limit effort="1" velocity="20" lower="0" upper="3.141592653589793116"/>
<joint_properties friction="0.0"/>
</joint>


</robot>
