<robot name="onshape">
<link name="mg995">
<visual>
<origin xyz="-0.01000000000000002276 -0.016412132034355746829 0.079500000000000542455" rpy="3.9376865725532636124e-15 -7.8090765985668229453e-17 -3.1415926535897917837" />
<geometry>
<mesh filename="package:///mg995.stl"/>
</geometry>
<material name="mg995_material">
<color rgba="0.10980392156862744946 0.10980392156862744946 0.10980392156862744946 1.0"/>
</material>
</visual>
<collision>
<origin xyz="-0.01000000000000002276 -0.016412132034355746829 0.079500000000000542455" rpy="3.9376865725532636124e-15 -7.8090765985668229453e-17 -3.1415926535897917837" />
<geometry>
<mesh filename="package:///mg995.stl"/>
</geometry>
</collision>
<inertial>
<origin xyz="-0.010167738547877702357 0.0026998501089926791978 0.079500007367541147829" rpy="0 0 0"/>
<mass value="0.058000000000000002942" />
<inertia ixx="8.8259081181983823949e-06" ixy="6.09742030955312171e-08"  ixz="4.358750759357996264e-12" iyy="9.8929114980025772736e-06" iyz="-5.6201381778835335189e-12" izz="1.4928256821169738454e-05" />
</inertial>
</link>

<link name="base_assembly">
<visual>
<origin xyz="-0.010000000000000000208 2.4651903288156618919e-32 -0.044499999999999990952" rpy="-1.570796326794896558 -3.3280069438939706576e-31 9.244463735242480589e-33" />
<geometry>
<mesh filename="package:///mg995.stl"/>
</geometry>
<material name="mg995_material">
<color rgba="0.10980392156862744946 0.10980392156862744946 0.10980392156862744946 1.0"/>
</material>
</visual>
<collision>
<origin xyz="-0.010000000000000000208 2.4651903288156618919e-32 -0.044499999999999990952" rpy="-1.570796326794896558 -3.3280069438939706576e-31 9.244463735242480589e-33" />
<geometry>
<mesh filename="package:///mg995.stl"/>
</geometry>
</collision>
<visual>
<origin xyz="-0.010000000000000001943 0.0022040872588556721136 -0.069499999999999742539" rpy="-4.9404924595820712449e-15 5.5511151231264593969e-17 -1.570796326794896336" />
<geometry>
<mesh filename="package:///base.stl"/>
</geometry>
<material name="base_material">
<color rgba="0.61568627450980395466 0.81176470588235294379 0.92941176470588238168 1.0"/>
</material>
</visual>
<collision>
<origin xyz="-0.010000000000000001943 0.0022040872588556721136 -0.069499999999999742539" rpy="-4.9404924595820712449e-15 5.5511151231264593969e-17 -1.570796326794896336" />
<geometry>
<mesh filename="package:///base.stl"/>
</geometry>
</collision>
<inertial>
<origin xyz="-0.0099750145467746090255 1.0974301085357882394e-09 -0.05217959169578513523" rpy="0 0 0"/>
<mass value="0.38938000000000000389" />
<inertia ixx="0.00061678854334413656026" ixy="-4.4197522516014831696e-12"  ixz="-3.2162502518402559174e-07" iyy="0.00030478316611731444234" iyz="-1.7068639553979511403e-11" izz="0.00077536641507061231007" />
</inertial>
</link>

<joint name="baseyaw" type="revolute">
<origin xyz="-0.010000000000000045311 1.7249945589578561902e-16 0.06950000000000049194" rpy="-5.5511151231269881802e-17 -4.9404924595819963031e-15 -3.1415926535897917837" />
<parent link="mg995" />
<child link="base_assembly" />
<axis xyz="0 0 1"/>
<limit effort="1" velocity="20" lower="0" upper="3.141592653589793116"/>
<joint_properties friction="0.0"/>
</joint>

<link name="arm">
<visual>
<origin xyz="-4.6178338930502604853e-15 0.089034298211335918816 0" rpy="-1.570796326794896336 -3.8514551507408452907e-17 1.57079632679489678" />
<geometry>
<mesh filename="package:///mg995.stl"/>
</geometry>
<material name="mg995_material">
<color rgba="0.10980392156862744946 0.10980392156862744946 0.10980392156862744946 1.0"/>
</material>
</visual>
<collision>
<origin xyz="-4.6178338930502604853e-15 0.089034298211335918816 0" rpy="-1.570796326794896336 -3.8514551507408452907e-17 1.57079632679489678" />
<geometry>
<mesh filename="package:///mg995.stl"/>
</geometry>
</collision>
<visual>
<origin xyz="-2.6437185773886540119e-15 0.049855142831802187753 -3.4694469519536141888e-18" rpy="1.570796326794896558 -1.2728436480038832844e-31 0" />
<geometry>
<mesh filename="package:///outarm.stl"/>
</geometry>
<material name="outarm_material">
<color rgba="0.61568627450980395466 0.81176470588235294379 0.92941176470588238168 1.0"/>
</material>
</visual>
<collision>
<origin xyz="-2.6437185773886540119e-15 0.049855142831802187753 -3.4694469519536141888e-18" rpy="1.570796326794896558 -1.2728436480038832844e-31 0" />
<geometry>
<mesh filename="package:///outarm.stl"/>
</geometry>
</collision>
<inertial>
<origin xyz="-6.0383968045202731794e-09 0.082046802534002524765 0.01521305220572925429" rpy="0 0 0"/>
<mass value="0.070766740240779890669" />
<inertia ixx="5.0581928568000623871e-05" ixy="7.4163074218630876267e-12"  ixz="7.2862191185929392053e-12" iyy="1.4192326667765158647e-05" iyz="-9.0300242728863300897e-06" izz="4.1085228957357491952e-05" />
</inertial>
</link>

<link name="outarm">
<visual>
<origin xyz="0.0491791553795336428 1.8596235662471372052e-15 -3.4694469519536141888e-18" rpy="1.570796326794896558 2.2646266752809325416e-31 1.570796326794896558" />
<geometry>
<mesh filename="package:///outarm.stl"/>
</geometry>
<material name="outarm_material">
<color rgba="0.61568627450980395466 0.81176470588235294379 0.92941176470588238168 1.0"/>
</material>
</visual>
<collision>
<origin xyz="0.0491791553795336428 1.8596235662471372052e-15 -3.4694469519536141888e-18" rpy="1.570796326794896558 2.2646266752809325416e-31 1.570796326794896558" />
<geometry>
<mesh filename="package:///outarm.stl"/>
</geometry>
</collision>
<inertial>
<origin xyz="0.049494116571571093732 2.0106976640098128582e-15 -0.0025000000000000035215" rpy="0 0 0"/>
<mass value="0.012766740240779891197" />
<inertia ixx="4.7912950654648213681e-07" ixy="1.1135912778498529877e-48"  ixz="8.8579500874283634074e-37" iyy="1.4306570639020504406e-05" iyz="9.6459463812490349565e-38" izz="1.4732505394563737546e-05" />
</inertial>
</link>

<joint name="armpitch" type="revolute">
<origin xyz="-4.8468173918791990218e-15 0.099034298211335955453 0.044500000000000275446" rpy="-3.1415926535897926719 -6.9474246886750598283e-18 -3.141592653589793116" />
<parent link="arm" />
<child link="outarm" />
<axis xyz="0 0 1"/>
<limit effort="1" velocity="20" lower="0" upper="3.141592653589793116"/>
<joint_properties friction="0.0"/>
</joint>

<joint name="basepitch" type="revolute">
<origin xyz="-0.020000000000000014294 0.028087867965644174734 0.07950000000000032041" rpy="1.5707963267948923392 1.6653345369377614347e-16 1.4447285194009526164e-15" />
<parent link="mg995" />
<child link="arm" />
<axis xyz="0 0 1"/>
<limit effort="1" velocity="20" lower="0" upper="3.141592653589793116"/>
<joint_properties friction="0.0"/>
</joint>


</robot>
