<robot name="onshape">
<link name="part_2_lf">
<visual>
<origin xyz="0.080000000000000737188 -0.13999999999999998557 0.025000000000000011796" rpy="3.141592653589793116 -0 0" />
<geometry>
<mesh filename="package:///part_3_left.stl"/>
</geometry>
<material name="part_3_left_material">
<color rgba="0.2313725490196078538 0.38039215686274507888 0.7058823529411765163 1.0"/>
</material>
</visual>
<collision>
<origin xyz="0.080000000000000737188 -0.13999999999999998557 0.025000000000000011796" rpy="3.141592653589793116 -0 0" />
<geometry>
<mesh filename="package:///part_3_left.stl"/>
</geometry>
</collision>
<visual>
<origin xyz="0.080000000000000737188 -0.1400000000000004019 0.019999999999999806127" rpy="3.141592653589793116 1.3877787807814456755e-15 -2.7755575615628913511e-15" />
<geometry>
<mesh filename="package:///part_12.stl"/>
</geometry>
<material name="part_12_material">
<color rgba="0.61568627450980395466 0.81176470588235294379 0.92941176470588238168 1.0"/>
</material>
</visual>
<collision>
<origin xyz="0.080000000000000737188 -0.1400000000000004019 0.019999999999999806127" rpy="3.141592653589793116 1.3877787807814456755e-15 -2.7755575615628913511e-15" />
<geometry>
<mesh filename="package:///part_12.stl"/>
</geometry>
</collision>
<visual>
<origin xyz="0.080000000000000737188 -0.13999999999999998557 0.020000000000000017764" rpy="3.141592653589793116 -0 0" />
<geometry>
<mesh filename="package:///part_2_lf.stl"/>
</geometry>
<material name="part_2_lf_material">
<color rgba="0.64705882352941179736 0.64705882352941179736 0.64705882352941179736 1.0"/>
</material>
</visual>
<collision>
<origin xyz="0.080000000000000737188 -0.13999999999999998557 0.020000000000000017764" rpy="3.141592653589793116 -0 0" />
<geometry>
<mesh filename="package:///part_2_lf.stl"/>
</geometry>
</collision>
<inertial>
<origin xyz="0.08000000000000072331 -0.14000000000000001332 0.018152173913043499059" rpy="0 0 0"/>
<mass value="0.361099999999999699" />
<inertia ixx="2.9512871376811721294e-05" ixy="-2.4402702081260895949e-19"  ixz="-1.7618285302889447053e-19" iyy="0.0042496728713768069929" iyz="-1.4209647951044757957e-20" izz="0.0042442333333333279871" />
</inertial>
</link>

<link name="part_2_lf_2">
<visual>
<origin xyz="-3.4694469519536141888e-18 0.26999999999999979572 -0.14999999999999996669" rpy="-1.570796326794896558 -1.5707963267948952257 0" />
<geometry>
<mesh filename="package:///part_2_lf.stl"/>
</geometry>
<material name="part_2_lf_material">
<color rgba="0.64705882352941179736 0.64705882352941179736 0.64705882352941179736 1.0"/>
</material>
</visual>
<collision>
<origin xyz="-3.4694469519536141888e-18 0.26999999999999979572 -0.14999999999999996669" rpy="-1.570796326794896558 -1.5707963267948952257 0" />
<geometry>
<mesh filename="package:///part_2_lf.stl"/>
</geometry>
</collision>
<visual>
<origin xyz="-1.7347234759768070944e-18 -0.010000000000000008882 -0.14999999999999999445" rpy="-1.570796326794896558 -1.570796326794896558 0" />
<geometry>
<mesh filename="package:///part_2_lf.stl"/>
</geometry>
<material name="part_2_lf_material">
<color rgba="0.64705882352941179736 0.64705882352941179736 0.64705882352941179736 1.0"/>
</material>
</visual>
<collision>
<origin xyz="-1.7347234759768070944e-18 -0.010000000000000008882 -0.14999999999999999445" rpy="-1.570796326794896558 -1.570796326794896558 0" />
<geometry>
<mesh filename="package:///part_2_lf.stl"/>
</geometry>
</collision>
<visual>
<origin xyz="0.014999999999999995975 0.13999999999999998557 -0.0099999999999999828609" rpy="1.570796326794896336 -1.232595164407830946e-32 -1.570796326794896558" />
<geometry>
<mesh filename="package:///part_3_left.stl"/>
</geometry>
<material name="part_3_left_material">
<color rgba="0.2313725490196078538 0.38039215686274507888 0.7058823529411765163 1.0"/>
</material>
</visual>
<collision>
<origin xyz="0.014999999999999995975 0.13999999999999998557 -0.0099999999999999828609" rpy="1.570796326794896336 -1.232595164407830946e-32 -1.570796326794896558" />
<geometry>
<mesh filename="package:///part_3_left.stl"/>
</geometry>
</collision>
<inertial>
<origin xyz="0.0081521739130434797693 0.13999999999999998557 -0.0099999999999999828609" rpy="0 0 0"/>
<mass value="0.36109999999999964349" />
<inertia ixx="0.0042442333333333262524" ixy="1.3552527156068805425e-20"  ixz="-1.9804955330263529244e-19" iyy="2.9512871376811704354e-05" iyz="7.1179982591421182953e-34" izz="0.0042496728713768052582" />
</inertial>
</link>

<joint name="sliderx" type="prismatic">
<origin xyz="0.0099999999999999811262 -0.13999999999999998557 0.0099999999999999984734" rpy="1.9721522630525295135e-31 1.570796326794896558 0" />
<parent link="part_2_lf" />
<child link="part_2_lf_2" />
<axis xyz="0 0 1"/>
<limit effort="1" velocity="20" lower="-0.022" upper="0.199"/>
<joint_properties friction="0.0"/>
</joint>


</robot>
