<?xml version="1.0"?>
<robot  xmlns:xacro="http://www.ros.org/wiki/xacro">

<link name="mg995">
<visual>
<origin xyz="0.014246661106962986085 0.018148050393590749174 0.007" rpy="2.9673693176031182817e-16 2.0210363832494955364e-17 -1.0512745417145308302" />
<geometry>
<mesh filename="file://$(find kai)/src/description/meshes/mg995.stl"/>
</geometry>
<material name="mg995_material">
<color rgba="0.10980392156862744946 0.10980392156862744946 0.10980392156862744946 1.0"/>
</material>
</visual>
<collision>
<origin xyz="0.014246661106962986085 0.018148050393590749174 0.007" rpy="2.9673693176031182817e-16 2.0210363832494955364e-17 -1.0512745417145308302" />
<geometry>
<mesh filename="file://$(find kai)/src/description/meshes/mg995.stl"/>
</geometry>
</collision>
<inertial>
<origin xyz="-0.0022603466340449626833 0.0085140121381946896884 0.007" rpy="0 0 0"/>
<mass value="0.058000000000000002942" />
<inertia ixx="9.6824739598764522283e-06" ixy="4.289189438683360203e-07"  ixz="2.714631065959707068e-12" iyy="9.0363456563254120714e-06" iyz="6.5738451268317901709e-12" izz="1.4928256821169687632e-05" />
</inertial>
</link>

<link name="base">
<visual>
<origin xyz="-0.010000000000000000208 1.5407439555097886824e-33 0.02" rpy="-1.570796326794896558 -4.8617306858290169587e-63 2.1849301382993296918e-62" />
<geometry>
<mesh filename="file://$(find kai)/src/description/meshes/mg995.stl"/>
</geometry>
<material name="mg995_material">
<color rgba="0.10980392156862744946 0.10980392156862744946 0.10980392156862744946 1.0"/>
</material>
</visual>
<collision>
<origin xyz="-0.010000000000000000208 1.5407439555097886824e-33 0.02" rpy="-1.570796326794896558 -4.8617306858290169587e-63 2.1849301382993296918e-62" />
<geometry>
<mesh filename="file://$(find kai)/src/description/meshes/mg995.stl"/>
</geometry>
</collision>
<visual>
<origin xyz="-0.010000000000000000208 0.0022040872588557892074 0" rpy="1.3096323621833190116e-32 1.5407439555098338415e-33 -1.570796326794896336" />
<geometry>
<mesh filename="file://$(find kai)/src/description/meshes/base.stl"/>
</geometry>
<material name="base_material">
<color rgba="0.61568627450980395466 0.81176470588235294379 0.92941176470588238168 1.0"/>
</material>
</visual>
<collision>
<origin xyz="-0.010000000000000000208 0.0022040872588557892074 0" rpy="1.3096323621833190116e-32 1.5407439555098338415e-33 -1.570796326794896336" />
<geometry>
<mesh filename="file://$(find kai)/src/description/meshes/base.stl"/>
</geometry>
</collision>
<inertial>
<origin xyz="-0.0099750145467746055561 1.0974301531947157137e-09 0.01" rpy="0 0 0"/>
<mass value="0.38937999999999994838" />
<inertia ixx="0.0006167885433441431739" ixy="-4.4197518122876652613e-12"  ixz="-3.2162502518126204087e-07" iyy="0.00030478316611731715285" iyz="-1.7068642800206643955e-11" izz="0.00077536641507063052466" />
</inertial>
</link>



<link name="upperarm">
<visual>
<origin xyz="-4.4755865680201623036e-15 0.089034298211336168616 -2.0816681711721685133e-17" rpy="-1.5707963267948970021 -1.2806630172647252295e-15 1.5707963267948992225" />
<geometry>
<mesh filename="file://$(find kai)/src/description/meshes/mg995.stl"/>
</geometry>
<material name="mg995_material">
<color rgba="0.10980392156862744946 0.10980392156862744946 0.10980392156862744946 1.0"/>
</material>
</visual>
<collision>
<origin xyz="-4.4755865680201623036e-15 0.089034298211336168616 -2.0816681711721685133e-17" rpy="-1.5707963267948970021 -1.2806630172647252295e-15 1.5707963267948992225" />
<geometry>
<mesh filename="file://$(find kai)/src/description/meshes/mg995.stl"/>
</geometry>
</collision>
<visual>
<origin xyz="-2.6229018956769323268e-15 0.049855142831802229386 -3.4694469519536141888e-18" rpy="1.570796326794896558 -1.1903935229434375023e-17 1.2883445191167409088e-18" />
<geometry>
<mesh filename="file://$(find kai)/src/description/meshes/outarm.stl"/>
</geometry>
<material name="outarm_material">
<color rgba="1 0 0 1.0"/>
</material>
</visual>
<collision>
<origin xyz="-2.6229018956769323268e-15 0.049855142831802229386 -3.4694469519536141888e-18" rpy="1.570796326794896558 -1.1903935229434375023e-17 1.2883445191167409088e-18" />
<geometry>
<mesh filename="file://$(find kai)/src/description/meshes/outarm.stl"/>
</geometry>
</collision>
<inertial>
<origin xyz="-6.0383965149735778233e-09 0.082046802534002719054 0.015213052205729075614" rpy="0 0 0"/>
<mass value="0.070766740240779890669" />
<inertia ixx="5.0581928568000264729e-05" ixy="7.4163072495860489721e-12"  ixz="7.286219165404532789e-12" iyy="1.4192326667764486103e-05" iyz="-9.0300242728862691033e-06" izz="4.1085228957357444518e-05" />
</inertial>
</link>

<link name="outarm">
<visual>
<origin xyz="0.049179155379533628922 1.8457457784393227485e-15 3.4694469519536141888e-18" rpy="1.570796326794896558 -5.0490281934899054697e-18 1.570796326794896558" />
<geometry>
<mesh filename="file://$(find kai)/src/description/meshes/outarm.stl"/>
</geometry>
<material name="outarm_material">
<color rgba="1 0 0 1.0"/>
</material>
</visual>
<collision>
<origin xyz="0.049179155379533628922 1.8457457784393227485e-15 3.4694469519536141888e-18" rpy="1.570796326794896558 -5.0490281934899054697e-18 1.570796326794896558" />
<geometry>
<mesh filename="file://$(find kai)/src/description/meshes/outarm.stl"/>
</geometry>
</collision>
<inertial>
<origin xyz="0.049494116571571072916 1.9966891635982488607e-15 -0.0024999999999999965826" rpy="0 0 0"/>
<mass value="0.012766740240779889462" />
<inertia ixx="4.7912950654648192505e-07" ixy="1.619544581867123556e-21"  ixz="-1.5771206474075741388e-22" iyy="1.4306570639020511183e-05" iyz="5.2019280474227799155e-25" izz="1.4732505394563737546e-05" />
</inertial>
</link>



<link name="world" />


<joint name="baselink_frame" type="fixed">
<parent link="world" />
<child link="base" />
<axis xyz="0 0 0"/>
</joint>

<joint name="baseyaw_joint" type="revolute">
<origin xyz="0 0 0.065" rpy="1.2325951644078287564e-32 -2.3111159332646792604e-33 1.570796326794896558" />
<parent link="base" />
<child link="mg995" />
<axis xyz="0 0 1"/>
<limit effort="1" velocity="20" lower="0" upper="3.14"/>
<dynamics damping="0.05" friction="0.05"/>
</joint>

<joint name="outarm_joint" type="revolute">
<origin xyz="-3.9621084191310274036e-15 0.099034298211335899942 0.043" rpy="-3.1415926535897900074 -2.1456705084130752623e-15 0.77445109514413923435" />
<parent link="upperarm" />
<child link="outarm" />
<axis xyz="0 0 1"/>
<limit effort="1" velocity="20" lower="-1.0" upper="2.141592653589793116"/>
<dynamics damping="0.05" friction="0.05"/>
</joint>

<joint name="baseroll_joint" type="revolute">
<origin xyz="-0.01941721109241918708 -0.012625212490669088933 0.009" rpy="1.5707963267948970021 -0.45450288711037684086 2.0903181118752649503" />
<parent link="mg995" />
<child link="upperarm" />
<axis xyz="0 0 1"/>
<limit effort="1" velocity="20" lower="-2.0" upper="1.141592653589793116"/>
<dynamics damping="0.05" friction="0.05"/>
</joint>



<!-- <gazebo>
    <plugin filename="ign_ros2_control-system" name="ign_ros2_control::IgnitionROS2ControlPlugin">
     <parameters>$(find kai)/config/kai_controller.yaml</parameters>
    </plugin>
</gazebo> -->

</robot>
