<robot name="onshape">
<link name="mg995">
<visual>
<origin xyz="-0.013303727591120374438 0.019610874574896863115 0.07950000000000007061" rpy="2.3280994003127006455e-23 2.2600776697932832155e-23 0.945181531987072443" />
<geometry>
<mesh filename="file://$(find kai)/src/description/mg995.stl"/>
</geometry>
<material name="mg995_material">
<color rgba="0.10980392156862744946 0.10980392156862744946 0.10980392156862744946 1.0"/>
</material>
</visual>
<collision>
<origin xyz="-0.013303727591120374438 0.019610874574896863115 0.07950000000000007061" rpy="2.3280994003127006455e-23 2.2600776697932832155e-23 0.945181531987072443" />
<geometry>
<mesh filename="file://$(find kai)/src/description/mg995.stl"/>
</geometry>
</collision>
<inertial>
<origin xyz="0.0022867342556930911682 0.008554948694575013543 0.079500007367540745373" rpy="0 0 0"/>
<mass value="0.058000000000000002942" />
<inertia ixx="9.4691249937282383014e-06" ixy="-5.2564672986162837526e-07"  ixz="-7.1081681655790567857e-12" iyy="9.24969462247289755e-06" iyz="-2.4208856088179703827e-13" izz="1.4928256821169670691e-05" />
</inertial>
</link>

<link name="assembly_1">
<visual>
<origin xyz="-4.4998726966838376029e-15 -0.089034298211336362905 -0.0050000000000000009714" rpy="1.5707963267948978903 -1.5204234980151919169e-16 -1.5707963267948981123" />
<geometry>
<mesh filename="file://$(find kai)/src/description/mg995.stl"/>
</geometry>
<material name="mg995_material">
<color rgba="0.10980392156862744946 0.10980392156862744946 0.10980392156862744946 1.0"/>
</material>
</visual>
<collision>
<origin xyz="-4.4998726966838376029e-15 -0.089034298211336362905 -0.0050000000000000009714" rpy="1.5707963267948978903 -1.5204234980151919169e-16 -1.5707963267948981123" />
<geometry>
<mesh filename="file://$(find kai)/src/description/mg995.stl"/>
</geometry>
</collision>
<visual>
<origin xyz="-2.6437185773886540119e-15 -0.049855142831802187753 -0.0050000000000000044409" rpy="-1.570796326794896558 -4.76201522709373384e-18 -1.5745245056061844283e-18" />
<geometry>
<mesh filename="file://$(find kai)/src/description/outarm.stl"/>
</geometry>
<material name="outarm_material">
<color rgba="0.61568627450980395466 0.81176470588235294379 0.92941176470588238168 1.0"/>
</material>
</visual>
<collision>
<origin xyz="-2.6437185773886540119e-15 -0.049855142831802187753 -0.0050000000000000044409" rpy="-1.570796326794896558 -4.76201522709373384e-18 -1.5745245056061844283e-18" />
<geometry>
<mesh filename="file://$(find kai)/src/description/outarm.stl"/>
</geometry>
</collision>
<inertial>
<origin xyz="-6.0383964152890371801e-09 -0.082046802534002857832 -0.020213052205728859745" rpy="0 0 0"/>
<mass value="0.070766740240779890669" />
<inertia ixx="5.0581928567999803943e-05" ixy="-7.4163072229242568395e-12"  ixz="-7.2862191842065565231e-12" iyy="1.4192326667764082915e-05" iyz="-9.0300242728862199754e-06" izz="4.108522895735734965e-05" />
</inertial>
</link>

<link name="outarm">
<visual>
<origin xyz="0.049179155379533656678 1.8596235662471372052e-15 1.3877787807814456755e-17" rpy="1.570796326794896558 -3.5389199373155208458e-17 1.570796326794896558" />
<geometry>
<mesh filename="file://$(find kai)/src/description/outarm.stl"/>
</geometry>
<material name="outarm_material">
<color rgba="0.61568627450980395466 0.81176470588235294379 0.92941176470588238168 1.0"/>
</material>
</visual>
<collision>
<origin xyz="0.049179155379533656678 1.8596235662471372052e-15 1.3877787807814456755e-17" rpy="1.570796326794896558 -3.5389199373155208458e-17 1.570796326794896558" />
<geometry>
<mesh filename="file://$(find kai)/src/description/outarm.stl"/>
</geometry>
</collision>
<inertial>
<origin xyz="0.049494116571571100671 2.0105976644640747209e-15 -0.0024999999999999861743" rpy="0 0 0"/>
<mass value="0.012766740240779891197" />
<inertia ixx="4.7912950654648192505e-07" ixy="-1.7505610802411016754e-22"  ixz="2.0292504453695975914e-23" iyy="1.4306570639020504406e-05" iyz="1.0876510635919964325e-21" izz="1.4732505394563737546e-05" />
</inertial>
</link>

<joint name="outarm" type="revolute">
<origin xyz="-3.6706748751669238118e-15 -0.099034298211335927697 -0.049499999999999128031" rpy="-4.1390834984404515333e-15 -1.0914910073606571169e-15 -1.6138091426053176036" />
<parent link="assembly_1" />
<child link="outarm" />
<axis xyz="0 0 1"/>
<limit effort="1" velocity="20" lower="0" upper="3.141592653589793116"/>
<joint_properties friction="0.0"/>
</joint>

<joint name="base" type="revolute">
<origin xyz="0.028570946193171013749 0.0015843545963584067249 0.079590287562755684947" rpy="-1.570796326794896558 -0.019341669366944650582 0.94518153198707821616" />
<parent link="mg995" />
<child link="assembly_1" />
<axis xyz="0 0 1"/>
<limit effort="1" velocity="20" />
<joint_properties friction="0.0"/>
</joint>

<link name="mg995_2">
<visual>
<origin xyz="-0.010000000000000000208 0 -0.044499999999999984013" rpy="-1.570796326794896558 -4.8617306858290169587e-63 2.1849301382993296918e-62" />
<geometry>
<mesh filename="file://$(find kai)/src/description/mg995.stl"/>
</geometry>
<material name="mg995_material">
<color rgba="0.10980392156862744946 0.10980392156862744946 0.10980392156862744946 1.0"/>
</material>
</visual>
<collision>
<origin xyz="-0.010000000000000000208 0 -0.044499999999999984013" rpy="-1.570796326794896558 -4.8617306858290169587e-63 2.1849301382993296918e-62" />
<geometry>
<mesh filename="file://$(find kai)/src/description/mg995.stl"/>
</geometry>
</collision>
<visual>
<origin xyz="-0.010000000000000000208 0.0022040872588557883401 -0.069499999999999964584" rpy="1.5407439555097907351e-33 -8.8592777441812602919e-33 -1.570796326794896558" />
<geometry>
<mesh filename="file://$(find kai)/src/description/base.stl"/>
</geometry>
<material name="base_material">
<color rgba="0.61568627450980395466 0.81176470588235294379 0.92941176470588238168 1.0"/>
</material>
</visual>
<collision>
<origin xyz="-0.010000000000000000208 0.0022040872588557883401 -0.069499999999999964584" rpy="1.5407439555097907351e-33 -8.8592777441812602919e-33 -1.570796326794896558" />
<geometry>
<mesh filename="file://$(find kai)/src/description/base.stl"/>
</geometry>
</collision>
<inertial>
<origin xyz="-0.0099750145467746055561 1.0974301550401260886e-09 -0.052179591695785218497" rpy="0 0 0"/>
<mass value="0.38937999999999994838" />
<inertia ixx="0.00061678854334414154759" ixy="-4.4197516790463694267e-12"  ixz="-3.2162502518126182911e-07" iyy="0.00030478316611731639391" iyz="-1.7068642796837126961e-11" izz="0.00077536641507062640469" />
</inertial>
</link>

<joint name="baseyaw" type="revolute">
<origin xyz="-6.9611571409717492764e-18 0.010000000000000005412 0.069500000000000089484" rpy="1.2325951644078287564e-32 -2.3111159332646792604e-33 1.570796326794896558" />
<parent link="mg995" />
<child link="mg995_2" />
<axis xyz="0 0 1"/>
<limit effort="1" velocity="20" lower="0" upper="3.141592653589793116"/>
<joint_properties friction="0.0"/>
</joint>


</robot>
